<?xml version="1.0" encoding="utf-8"?>
<!-- This URDF was automatically created by SolidWorks to URDF Exporter! Originally created by
Stephen Brawner (brawner@gmail.com) 
     Commit Version: 1.5.1-0-g916b5db  Build Version: 1.5.7152.31018
     For more information, please see http://wiki.ros.org/sw_urdf_exporter -->
<robot
  name="robotic_arm">
  <link name="world" />
  <joint name="base_joint" type="fixed">
    <parent link="world" />
    <child link="base_link" />
    <origin rpy="0 0 0" xyz="0.0 0.0 0.0" />
  </joint>
  <link
    name="base_link">
    <inertial>
      <origin
        xyz="0.000454528386228833 -0.000302669270904221 0.0302331731944049"
        rpy="0 0 0" />
      <mass
        value="0.555206588878508" />
      <inertia
        ixx="0.00100566469503316"
        ixy="-1.36920441366169E-05"
        ixz="-6.05386038711752E-07"
        iyy="0.00099809821083753"
        iyz="2.78623219846149E-07"
        izz="0.00194501574960672" />
    </inertial>
    <self_collide>true</self_collide>

    <visual>
      <origin
        xyz="0 0 0"
        rpy="0 0 0" />
      <geometry>
        <mesh
          filename="file://$(find robotic_arm)/meshes/base_link.STL" />
      </geometry>
      <material
        name="">
        <color
          rgba="0.501960784313725 0.501960784313725 0.501960784313725 1" />
      </material>
    </visual>
    <collision>
      <origin
        xyz="0 0 0"
        rpy="0 0 0" />
      <geometry>
        <mesh
          filename="file://$(find robotic_arm)/meshes/base_link.STL" />
      </geometry>
    </collision>
  </link>
  <link
    name="link_1">
    <inertial>
      <origin
        xyz="-0.00129528059724605 -0.00183017478543235 -0.000105390902916391"
        rpy="0 0 0" />
      <mass
        value="0.368463521364962" />
      <inertia
        ixx="0.000589336378921301"
        ixy="6.76692982782835E-16"
        ixz="3.36153373241822E-15"
        iyy="0.00101850958801356"
        iyz="1.91925947447566E-07"
        izz="0.000551134485833059" />
    </inertial>
    <self_collide>true</self_collide>
    <visual>
      <origin
        xyz="0 0 0"
        rpy="0 0 0" />
      <geometry>
        <mesh
          filename="file://$(find robotic_arm)/meshes/link_1.STL" />
      </geometry>
      <material
        name="">
        <color
          rgba="0.501960784313725 0.501960784313725 0.501960784313725 1" />
      </material>
    </visual>
    <collision>
      <origin
        xyz="0 0 0"
        rpy="0 0 0" />
      <geometry>
        <mesh
          filename="file://$(find robotic_arm)/meshes/link_1.STL" />
      </geometry>
    </collision>
  </link>
  <joint
    name="joint_1"
    type="revolute">
    <origin
      xyz="0 0 0.09225"
      rpy="-1.5708 0 0" />
    <parent
      link="base_link" />
    <child
      link="link_1" />
    <axis
      xyz="0 1 0" />
    <limit
      lower="0"
      upper="6.283"
      effort="300"
      velocity="3" />
  </joint>
  <link
    name="link_2">
    <inertial>
      <origin
        xyz="-0.0173938365175276 2.48134846003722E-14 -0.0932380394807353"
        rpy="0 0 0" />
      <mass
        value="0.460676266929449" />
      <inertia
        ixx="0.00184587833790606"
        ixy="-7.66246505564162E-13"
        ixz="1.59351514099875E-06"
        iyy="0.00171083372728511"
        iyz="1.56054259537726E-13"
        izz="0.00016644976368905" />
    </inertial>
    <self_collide>true</self_collide>
    <visual>
      <origin
        xyz="0 0 0"
        rpy="0 0 0" />
      <geometry>
        <mesh
          filename="file://$(find robotic_arm)/meshes/link_2.STL" />
      </geometry>
      <material
        name="">
        <color
          rgba="0.501960784313725 0.501960784313725 0.501960784313725 1" />
      </material>
    </visual>
    <collision>
      <origin
        xyz="0 0 0"
        rpy="0 0 0" />
      <geometry>
        <mesh
          filename="file://$(find robotic_arm)/meshes/link_2.STL" />
      </geometry>
    </collision>
  </link>
  <joint
    name="joint_2"
    type="revolute">
    <origin
      xyz="0.01266 -0.043 0"
      rpy="-1.5788 0 0" />
    <parent
      link="link_1" />
    <child
      link="link_2" />
    <axis
      xyz="1 0 0" />
    <limit
      lower="-1.57"
      upper="1.57"
      effort="300"
      velocity="3" />
  </joint>
  <link
    name="link_3">
    <inertial>
      <origin
        xyz="0.000113073323768614 -0.000707151250188505 -0.0578023076202162"
        rpy="0 0 0" />
      <mass
        value="0.233433056175268" />
      <inertia
        ixx="0.000571109636740069"
        ixy="-1.86652936947289E-08"
        ixz="2.50143892078807E-08"
        iyy="0.000533764178562199"
        iyz="-4.65917846588896E-06"
        izz="7.15009693491387E-05" />
    </inertial>
    <self_collide>true</self_collide>
    <visual>
      <origin
        xyz="0 0 0"
        rpy="0 0 0" />
      <geometry>
        <mesh
          filename="file://$(find robotic_arm)/meshes/link_3.STL" />
      </geometry>
      <material
        name="">
        <color
          rgba="0.501960784313725 0.501960784313725 0.501960784313725 1" />
      </material>
    </visual>
    <collision>
      <origin
        xyz="0 0 0"
        rpy="0 0 0" />
      <geometry>
        <mesh
          filename="file://$(find robotic_arm)/meshes/link_3.STL" />
      </geometry>
    </collision>
  </link>
  <joint
    name="joint_3"
    type="revolute">
    <origin
      xyz="-0.0184 0 -0.185"
      rpy="-1.5696 0 3.1416" />
    <parent
      link="link_2" />
    <child
      link="link_3" />
    <axis
      xyz="1 0 0" />
    <limit
      lower="-1.0"
      upper="4.14"
      effort="300"
      velocity="3" />
  </joint>
  <link
    name="link_4">
    <inertial>
      <origin
        xyz="-0.0164766971219827 -0.00214733921697745 -0.0395286263542515"
        rpy="0 0 0" />
      <mass
        value="0.237132435221668" />
      <inertia
        ixx="0.0002320004492489"
        ixy="7.92790751917672E-21"
        ixz="-2.51724359466701E-07"
        iyy="0.000175352374553037"
        iyz="-6.09805618217261E-08"
        izz="7.77538891579693E-05" />
    </inertial>
    <self_collide>true</self_collide>
    <visual>
      <origin
        xyz="0 0 0"
        rpy="0 0 0" />
      <geometry>
        <mesh
          filename="file://$(find robotic_arm)/meshes/link_4.STL" />
      </geometry>
      <material
        name="">
        <color
          rgba="0.501960784313725 0.501960784313725 0.501960784313725 1" />
      </material>
    </visual>
    <collision>
      <origin
        xyz="0 0 0"
        rpy="0 0 0" />
      <geometry>
        <mesh
          filename="file://$(find robotic_arm)/meshes/link_4.STL" />
      </geometry>
    </collision>
  </link>
  <joint
    name="joint_4"
    type="revolute">
    <origin
      xyz="-0.0184 0 -0.1175"
      rpy="0.0054027 0 3.1416" />
    <parent
      link="link_3" />
    <child
      link="link_4" />
    <axis
      xyz="1 0 0" />
    <limit
      lower="-2.14"
      upper="2.14"
      effort="300"
      velocity="3" />
  </joint>
  <link
    name="link_5">
    <inertial>
      <origin
        xyz="2.76519416878007E-07 0.0233833245740031 0.000606183982249847"
        rpy="0 0 0" />
      <mass
        value="0.050610365817931" />
      <inertia
        ixx="4.21509740108801E-05"
        ixy="1.56919564397777E-13"
        ixz="1.96823158449653E-13"
        iyy="4.53193193640307E-05"
        iyz="2.15367686640589E-06"
        izz="7.46329001603445E-06" />
    </inertial>
    <self_collide>true</self_collide>
    <visual>
      <origin
        xyz="0 0 0"
        rpy="0 0 0" />
      <geometry>
        <mesh
          filename="file://$(find robotic_arm)/meshes/link_5.STL" />
      </geometry>
      <material
        name="">
        <color
          rgba="0.501960784313725 0.501960784313725 0.501960784313725 1" />
      </material>
    </visual>
    <collision>
      <origin
        xyz="0 0 0"
        rpy="0 0 0" />
      <geometry>
        <mesh
          filename="file://$(find robotic_arm)/meshes/link_5.STL" />
      </geometry>
    </collision>
  </link>
  <joint
    name="joint_5"
    type="fixed">
    <origin
      xyz="-0.01865 0.0073984 -0.12777"
      rpy="0 0 -3.1416" />
    <parent
      link="link_4" />
    <child
      link="link_5" />
    <axis
      xyz="0 0 -1" />
    <limit
      lower="-6.283"
      upper="6.283"
      effort="300"
      velocity="3" />
  </joint>
  <link
    name="eef_link_r">
    <inertial>
      <origin
        xyz="-0.0176853779723258 -0.0112790007486472 -0.0204831374002998"
        rpy="0 0 0" />
      <mass
        value="0.0235861713981624" />
      <inertia
        ixx="1.84146067739889E-05"
        ixy="2.53501114470455E-07"
        ixz="-2.03988901053199E-06"
        iyy="2.05791529306359E-05"
        iyz="1.71928521769893E-06"
        izz="3.36503087469021E-06" />
    </inertial>
    <self_collide>true</self_collide>
    <visual>
      <origin
        xyz="0 0 0"
        rpy="0 0 0" />
      <geometry>
        <mesh
          filename="file://$(find robotic_arm)/meshes/eef_link_r.STL" />
      </geometry>
      <material
        name="">
        <color
          rgba="0.501960784313725 0.501960784313725 0.501960784313725 1" />
      </material>
    </visual>
    <collision>
      <origin
        xyz="0 0 0"
        rpy="0 0 0" />
      <geometry>
        <mesh
          filename="file://$(find robotic_arm)/meshes/eef_link_r.STL" />
      </geometry>
    </collision>
  </link>
  <joint
    name="eef_joint_r"
    type="revolute">
    <origin
      xyz="0 0.015 -0.03475"
      rpy="0 0.37686 3.1416" />
    <parent
      link="link_5" />
    <child
      link="eef_link_r" />
    <axis
      xyz="0 1 0" />
    <limit
      lower="-0.3"
      upper="0.3"
      effort="300"
      velocity="3" />
  </joint>
  <link
    name="eef_link_l">
    <inertial>
      <origin
        xyz="-0.0176852937948024 0.00622199674148659 -0.0204832377983133"
        rpy="0 0 0" />
      <mass
        value="0.0235861589775242" />
      <inertia
        ixx="1.84147275050698E-05"
        ixy="2.53492698038198E-07"
        ixz="-2.03990695003512E-06"
        iyy="2.05791818527812E-05"
        iyz="1.71929551412545E-06"
        izz="3.36493835662023E-06" />
    </inertial>
    <self_collide>true</self_collide>
    <visual>
      <origin
        xyz="0 0 0"
        rpy="0 0 0" />
      <geometry>
        <mesh
          filename="file://$(find robotic_arm)/meshes/eef_link_l.STL" />
      </geometry>
      <material
        name="">
        <color
          rgba="0.501960784313725 0.501960784313725 0.501960784313725 1" />
      </material>
    </visual>
    <collision>
      <origin
        xyz="0 0 0"
        rpy="0 0 0" />
      <geometry>
        <mesh
          filename="file://$(find robotic_arm)/meshes/eef_link_l.STL" />
      </geometry>
    </collision>
  </link>
  <joint
    name="eef_joint_l"
    type="revolute">
    <origin
      xyz="0 0.02 -0.03475"
      rpy="0 0.26836 0" />
    <parent
      link="link_5" />
    <child
      link="eef_link_l" />
    <axis
      xyz="0 -1 0" />
    <limit
      lower="-0.3"
      upper="0.3"
      effort="300"
      velocity="3" />
  </joint>

  <transmission name="link_1_trans">
    <type>transmission_interface/SimpleTransmission</type>
    <joint name="joint_1">
      <hardwareInterface>hardware_interface/PositionJointInterface</hardwareInterface>
    </joint>
    <actuator name="link_1_motor">
      <hardwareInterface>hardware_interface/PositionJointInterface</hardwareInterface>
      <mechanicalReduction>1</mechanicalReduction>
    </actuator>
  </transmission>

  <transmission name="link_2_trans">
    <type>transmission_interface/SimpleTransmission</type>
    <joint name="joint_2">
      <hardwareInterface>hardware_interface/PositionJointInterface</hardwareInterface>
    </joint>
    <actuator name="link_2_motor">
      <hardwareInterface>hardware_interface/PositionJointInterface</hardwareInterface>
      <mechanicalReduction>1</mechanicalReduction>
    </actuator>
  </transmission>

  <transmission name="link_3_trans">
    <type>transmission_interface/SimpleTransmission</type>
    <joint name="joint_3">
      <hardwareInterface>hardware_interface/PositionJointInterface</hardwareInterface>
    </joint>
    <actuator name="link_3_motor">
      <hardwareInterface>hardware_interface/PositionJointInterface</hardwareInterface>
      <mechanicalReduction>1</mechanicalReduction>
    </actuator>
  </transmission>

  <transmission name="link_4_trans">
    <type>transmission_interface/SimpleTransmission</type>
    <joint name="joint_4">
      <hardwareInterface>hardware_interface/PositionJointInterface</hardwareInterface>
    </joint>
    <actuator name="link_4_motor">
      <hardwareInterface>hardware_interface/PositionJointInterface</hardwareInterface>
      <mechanicalReduction>1</mechanicalReduction>
    </actuator>
  </transmission>

  <transmission name="eef_link_r_trans">
    <type>transmission_interface/SimpleTransmission</type>
    <joint name="eef_joint_r">
      <hardwareInterface>hardware_interface/PositionJointInterface</hardwareInterface>
    </joint>
    <actuator name="eef_link_r_motor">
      <hardwareInterface>hardware_interface/PositionJointInterface</hardwareInterface>
      <mechanicalReduction>1</mechanicalReduction>
    </actuator>
  </transmission>

  <transmission name="eef_link_l_trans">
    <type>transmission_interface/SimpleTransmission</type>
    <joint name="eef_joint_l">
      <hardwareInterface>hardware_interface/PositionJointInterface</hardwareInterface>
    </joint>
    <actuator name="eef_link_l_motor">
      <hardwareInterface>hardware_interface/PositionJointInterface</hardwareInterface>
      <mechanicalReduction>1</mechanicalReduction>
    </actuator>
  </transmission>

  <ros2_control name="robotic_arm_controller" type="system">
    
  </ros2_control>  

  <gazebo>
    <plugin filename="libgazebo_ros2_control.so" name="gazebo_ros2_control">
      <robot_param>robot_description</robot_param>
      <robot_param_node>robot_state_publisher</robot_param_node>
      <parameters>$(find robotic_arm)/config/ros_controllers.yaml</parameters>
      <!-- <controller_manager_name>simulation_controller_manager</controller_manager_name> -->
    </plugin>
  </gazebo>


</robot>